Workbook

Sheet Student_Data
A1: id | B1: Name | C1: Gender | D1: Age | E1: Section | F1: Science | G1: English | H1: History | I1: Maths | J1: Total Marks | K1: Average marks | L1: Percentage | M1: Grade | N1: Result | O1: Performance
A2: 1 | B2: Bronnie | C2: Female | D2: 13 | E2: C | F2: 21 | G2: 81 | H2: 62 | I2: 49 | J2: =SUM(F2:I2) -> 213 | K2: =AVERAGE(F2:I2) -> 53.25 | L2: =J2/400 -> 0.5325 | M2: =IF(L2>=90%,"A+", IF(L2>=80%, "A", IF(L2>=70%, "B", IF(L2>=60%, "C", IF(L2>=50%, "D", "F"))))) -> D | N2: =IF(L2>=50%, "PASS", "FAIL") -> PASS | O2: =IF(L2>=85%, "EXCELLENT", IF(L2>=70%, "GOOD", IF(L2>=50%, "Needs Improvement", "At Risk"))) -> Needs Improvement
A3: 2 | B3: Lemmie | C3: Male | D3: 15 | E3: B | F3: 29 | G3: 41 | H3: 17 | I3: 40 | J3: =SUM(F3:I3) -> 127 | K3: =AVERAGE(F3:I3) -> 31.75 | L3: =J3/400 -> 0.3175 | M3: =IF(L3>=90%,"A+", IF(L3>=80%, "A", IF(L3>=70%, "B", IF(L3>=60%, "C", IF(L3>=50%, "D", "F"))))) -> F | N3: =IF(L3>=50%, "PASS", "FAIL") -> FAIL | O3: =IF(L3>=85%, "EXCELLENT", IF(L3>=70%, "GOOD", IF(L3>=50%, "Needs Improvement", "At Risk"))) -> At Risk
A4: 3 | B4: Danya | C4: Female | D4: 14 | E4: C | F4: 12 | G4: 87 | H4: 16 | I4: 96 | J4: =SUM(F4:I4) -> 211 | K4: =AVERAGE(F4:I4) -> 52.75 | L4: =J4/400 -> 0.5275 | M4: =IF(L4>=90%,"A+", IF(L4>=80%, "A", IF(L4>=70%, "B", IF(L4>=60%, "C", IF(L4>=50%, "D", "F"))))) -> D | N4: =IF(L4>=50%, "PASS", "FAIL") -> PASS | O4: =IF(L4>=85%, "EXCELLENT", IF(L4>=70%, "GOOD", IF(L4>=50%, "Needs Improvement", "At Risk"))) -> Needs Improvement
A5: 4 | B5: Denna | C5: Female | D5: 14 | E5: B | F5: 15 | G5: 53 | H5: 82 | I5: 33 | J5: =SUM(F5:I5) -> 183 | K5: =AVERAGE(F5:I5) -> 45.75 | L5: =J5/400 -> 0.4575 | M5: =IF(L5>=90%,"A+", IF(L5>=80%, "A", IF(L5>=70%, "B", IF(L5>=60%, "C", IF(L5>=50%, "D", "F"))))) -> F | N5: =IF(L5>=50%, "PASS", "FAIL") -> FAIL | O5: =IF(L5>=85%, "EXCELLENT", IF(L5>=70%, "GOOD", IF(L5>=50%, "Needs Improvement", "At Risk"))) -> At Risk
A6: 5 | B6: Jocelin | C6: Male | D6: 14 | E6: A | F6: 43 | G6: 6 | H6: 3 | I6: 21 | J6: =SUM(F6:I6) -> 73 | K6: =AVERAGE(F6:I6) -> 18.25 | L6: =J6/400 -> 0.1825 | M6: =IF(L6>=90%,"A+", IF(L6>=80%, "A", IF(L6>=70%, "B", IF(L6>=60%, "C", IF(L6>=50%, "D", "F"))))) -> F | N6: =IF(L6>=50%, "PASS", "FAIL") -> FAIL | O6: =IF(L6>=85%, "EXCELLENT", IF(L6>=70%, "GOOD", IF(L6>=50%, "Needs Improvement", "At Risk"))) -> At Risk
A7: 6 | B7: Malissa | C7: Female | D7: 14 | E7: C | F7: 98 | G7: 51 | H7: 85 | I7: 76 | J7: =SUM(F7:I7) -> 310 | K7: =AVERAGE(F7:I7) -> 77.5 | L7: =J7/400 -> 0.775 | M7: =IF(L7>=90%,"A+", IF(L7>=80%, "A", IF(L7>=70%, "B", IF(L7>=60%, "C", IF(L7>=50%, "D", "F"))))) -> B | N7: =IF(L7>=50%, "PASS", "FAIL") -> PASS | O7: =IF(L7>=85%, "EXCELLENT", IF(L7>=70%, "GOOD", IF(L7>=50%, "Needs Improvement", "At Risk"))) -> GOOD
A8: 7 | B8: Ichabod | C8: Female | D8: 14 | E8: B | F8: 38 | G8: 74 | H8: 54 | I8: 60 | J8: =SUM(F8:I8) -> 226 | K8: =AVERAGE(F8:I8) -> 56.5 | L8: =J8/400 -> 0.565 | M8: =IF(L8>=90%,"A+", IF(L8>=80%, "A", IF(L8>=70%, "B", IF(L8>=60%, "C", IF(L8>=50%, "D", "F"))))) -> D | N8: =IF(L8>=50%, "PASS", "FAIL") -> PASS | O8: =IF(L8>=85%, "EXCELLENT", IF(L8>=70%, "GOOD", IF(L8>=50%, "Needs Improvement", "At Risk"))) -> Needs Improvement
A9: 8 | B9: Beverlie | C9: Male | D9: 14 | E9: B | F9: 25 | G9: 51 | H9: 41 | I9: 80 | J9: =SUM(F9:I9) -> 197 | K9: =AVERAGE(F9:I9) -> 49.25 | L9: =J9/400 -> 0.4925 | M9: =IF(L9>=90%,"A+", IF(L9>=80%, "A", IF(L9>=70%, "B", IF(L9>=60%, "C", IF(L9>=50%, "D", "F"))))) -> F | N9: =IF(L9>=50%, "PASS", "FAIL") -> FAIL | O9: =IF(L9>=85%, "EXCELLENT", IF(L9>=70%, "GOOD", IF(L9>=50%, "Needs Improvement", "At Risk"))) -> At Risk
A10: 9 | B10: Corrine | C10: Male | D10: 15 | E10: A | F10: 39 | G10: 16 | H10: 22 | I10: 49 | J10: =SUM(F10:I10) -> 126 | K10: =AVERAGE(F10:I10) -> 31.5 | L10: =J10/400 -> 0.315 | M10: =IF(L10>=90%,"A+", IF(L10>=80%, "A", IF(L10>=70%, "B", IF(L10>=60%, "C", IF(L10>=50%, "D", "F"))))) -> F | N10: =IF(L10>=50%, "PASS", "FAIL") -> FAIL | O10: =IF(L10>=85%, "EXCELLENT", IF(L10>=70%, "GOOD", IF(L10>=50%, "Needs Improvement", "At Risk"))) -> At Risk
A11: 10 | B11: Tate | C11: Male | D11: 15 | E11: C | F11: 35 | G11: 25 | H11: 37 | I11: 27 | J11: =SUM(F11:I11) -> 124 | K11: =AVERAGE(F11:I11) -> 31 | L11: =J11/400 -> 0.31 | M11: =IF(L11>=90%,"A+", IF(L11>=80%, "A", IF(L11>=70%, "B", IF(L11>=60%, "C", IF(L11>=50%, "D", "F"))))) -> F | N11: =IF(L11>=50%, "PASS", "FAIL") -> FAIL | O11: =IF(L11>=85%, "EXCELLENT", IF(L11>=70%, "GOOD", IF(L11>=50%, "Needs Improvement", "At Risk"))) -> At Risk
A12: 11 | B12: Dunn | C12: Male | D12: 15 | E12: C | F12: 100 | G12: 93 | H12: 87 | I12: 81 | J12: =SUM(F12:I12) -> 361 | K12: =AVERAGE(F12:I12) -> 90.25 | L12: =J12/400 -> 0.9025 | M12: =IF(L12>=90%,"A+", IF(L12>=80%, "A", IF(L12>=70%, "B", IF(L12>=60%, "C", IF(L12>=50%, "D", "F"))))) -> A+ | N12: =IF(L12>=50%, "PASS", "FAIL") -> PASS | O12: =IF(L12>=85%, "EXCELLENT", IF(L12>=70%, "GOOD", IF(L12>=50%, "Needs Improvement", "At Risk"))) -> EXCELLENT
A13: 12 | B13: Valaria | C13: Male | D13: 13 | E13: B | F13: 19 | G13: 5 | H13: 78 | I13: 76 | J13: =SUM(F13:I13) -> 178 | K13: =AVERAGE(F13:I13) -> 44.5 | L13: =J13/400 -> 0.445 | M13: =IF(L13>=90%,"A+", IF(L13>=80%, "A", IF(L13>=70%, "B", IF(L13>=60%, "C", IF(L13>=50%, "D", "F"))))) -> F | N13: =IF(L13>=50%, "PASS", "FAIL") -> FAIL | O13: =IF(L13>=85%, "EXCELLENT", IF(L13>=70%, "GOOD", IF(L13>=50%, "Needs Improvement", "At Risk"))) -> At Risk
... A251: 250 | B251: Fernande | C251: Male | D251: 15 | E251: B | F251: 50 | G251: 8 | H251: 80 | I251: 78 | J251: =SUM(F251:I251) -> 216 | K251: =AVERAGE(F251:I251) -> 54 | L251: =J251/400 -> 0.54 | M251: =IF(L251>=90%,"A+", IF(L251>=80%, "A", IF(L251>=70%, "B", IF(L251>=60%, "C", IF(L251>=50%, "D", "F"))))) -> D | N251: =IF(L251>=50%, "PASS", "FAIL") -> PASS | O251: =IF(L251>=85%, "EXCELLENT", IF(L251>=70%, "GOOD", IF(L251>=50%, "Needs Improvement", "At Risk"))) -> Needs Improvement

Sheet Analysis
A1: STUDENT PERFORMANCE ANALYSIS | D1: Subject Performance Analysis | H1: Grade Distribution
A2: Total Students | B2: =COUNTA(Student_Data!A2:A251) -> 250 | D2: Subject | E2: Average Marks | H2: Grade | I2: Students
A3: Average Percentage | B3: =AVERAGE(Student_Data!L2:L251) -> 0.51177 | D3: Science | E3: =AVERAGE(Student_Data!F2:F251) -> 51.44 | H3: A+ | I3: =COUNTIF(Student_Data!M2:M251,"A+") -> 1
A4: Pass Rate | B4: =COUNTIF(Student_Data!N2:N251,"Pass")/COUNTA(Student_Data!N2:N251) -> 0.52 | D4: English | E4: =AVERAGE(Student_Data!G2:G251) -> 47.98 | H4: A | I4: =COUNTIF(Student_Data!M2:M251,"A") -> 6
A5: Highest Percentage | B5: =MAX(Student_Data!L2:L251) -> 0.9025 | D5: History | E5: =AVERAGE(Student_Data!G2:G251) -> 47.98 | H5: B | I5: =COUNTIF(Student_Data!M2:M251,"B") -> 17
A6: Lowest Percentage | B6: =MIN(Student_Data!L2:L251) -> 0.1425 | D6: Maths | E6: =AVERAGE(Student_Data!H2:H251) -> 52.272 | H6: C | I6: =COUNTIF(Student_Data!M2:M251,"C") -> 49
A7: Excellent Students | B7: =COUNTIF(Student_Data!O2:O251,"Excellent") -> 4 | H7: D | I7: =COUNTIF(Student_Data!M2:M251,"D") -> 57
A8: At Risk Students | B8: =COUNTIF(Student_Data!O2:O251,"At Risk") -> 120 | H8: F | I8: =COUNTIF(Student_Data!M2:M251,"F") -> 120
D10: Section | E10: Number of Students | F10: Average Percentage | H10: Rank | I10: Student name | J10: Section | K10: Percentage
D11: A | E11: =COUNTIF(Student_Data!E2:E251,"A") -> 79 | F11: =AVERAGEIF(Student_Data!E2:E251,"A",Student_Data!L2:L251) -> 0.52063291 | H11: 1 | I11: {=INDEX(_xlfn.ANCHORARRAY($M$11),H11,1)} -> Dunn | J11: {=INDEX(_xlfn.ANCHORARRAY($M$11),H11,2)} -> C | K11: {=INDEX(_xlfn.ANCHORARRAY($M$11),H11,3)} -> 0.9025 | M11: {=_xlfn.SORTBY(CHOOSE({1,2,3},Student_Data!B2:B251,Student_Data!E2:E251,Student_Data!L2:L251),Student_Data!L2:L251,-1)} -> Dunn | N11: C | O11: 0.9025 | Q11: {=_xlfn.SORTBY(CHOOSE({1,2,3},Student_Data!B2:B251,Student_Data!E2:E251,Student_Data!L2:L251),Student_Data!L2:L251,1)} -> Ginnifer | R11: C | S11: 0.1425
D12: B | E12: =COUNTIF(Student_Data!E2:E251,"B") -> 79 | F12: =AVERAGEIF(Student_Data!E2:E251,"A",Student_Data!L2:L251) -> 0.52063291 | H12: 2 | I12: {=INDEX(_xlfn.ANCHORARRAY($M$11),H12,1)} -> Patrizia | J12: {=INDEX(_xlfn.ANCHORARRAY($M$11),H12,2)} -> A | K12: {=INDEX(_xlfn.ANCHORARRAY($M$11),H12,3)} -> 0.89 | M12: Patrizia | N12: A | O12: 0.89 | Q12: Ashlan | R12: B | S12: 0.1675
D13: C | E13: =COUNTIF(Student_Data!E2:E251,"C") -> 92 | F13: =AVERAGEIF(Student_Data!E2:E251,"B",Student_Data!L2:L251) -> 0.52490506 | H13: 3 | I13: {=INDEX(_xlfn.ANCHORARRAY($M$11),H13,1)} -> Nil | J13: {=INDEX(_xlfn.ANCHORARRAY($M$11),H13,2)} -> A | K13: {=INDEX(_xlfn.ANCHORARRAY($M$11),H13,3)} -> 0.8675 | M13: Nil | N13: A | O13: 0.8675 | Q13: Blake | R13: B | S13: 0.175
H14: 4 | I14: {=INDEX(_xlfn.ANCHORARRAY($M$11),H14,1)} -> Daffi | J14: {=INDEX(_xlfn.ANCHORARRAY($M$11),H14,2)} -> A | K14: {=INDEX(_xlfn.ANCHORARRAY($M$11),H14,3)} -> 0.8525 | M14: Daffi | N14: A | O14: 0.8525 | Q14: Jocelin | R14: A | S14: 0.1825
H15: 5 | I15: {=INDEX(_xlfn.ANCHORARRAY($M$11),H15,1)} -> Ruddie | J15: {=INDEX(_xlfn.ANCHORARRAY($M$11),H15,2)} -> B | K15: {=INDEX(_xlfn.ANCHORARRAY($M$11),H15,3)} -> 0.8325 | M15: Ruddie | N15: B | O15: 0.8325 | Q15: Berget | R15: C | S15: 0.1825
D16: Gender | E16: Number of Students | F16: Average Percentage | H16: 6 | I16: {=INDEX(_xlfn.ANCHORARRAY($M$11),H16,1)} -> Herold | J16: {=INDEX(_xlfn.ANCHORARRAY($M$11),H16,2)} -> A | K16: {=INDEX(_xlfn.ANCHORARRAY($M$11),H16,3)} -> 0.8 | M16: Herold | N16: A | O16: 0.8 | Q16: Josepha | R16: C | S16: 0.1925
D17: Female | E17: =COUNTIF(Student_Data!C2:C251, "Female") -> 118 | F17: =AVERAGEIF(Student_Data!C2:C251,"Female",Student_Data!L2:L251) -> 0.50654661 | H17: 7 | I17: {=INDEX(_xlfn.ANCHORARRAY($M$11),H17,1)} -> Val | J17: {=INDEX(_xlfn.ANCHORARRAY($M$11),H17,2)} -> B | K17: {=INDEX(_xlfn.ANCHORARRAY($M$11),H17,3)} -> 0.8 | M17: Val | N17: B | O17: 0.8 | Q17: Nickie | R17: C | S17: 0.195
D18: Male | E18: =COUNTIF(Student_Data!C2:C251, "Male") -> 132 | F18: =AVERAGEIF(Student_Data!C2:C251,"Male",Student_Data!L2:L251) -> 0.51643939 | H18: 8 | I18: {=INDEX(_xlfn.ANCHORARRAY($M$11),H18,1)} -> Luelle | J18: {=INDEX(_xlfn.ANCHORARRAY($M$11),H18,2)} -> B | K18: {=INDEX(_xlfn.ANCHORARRAY($M$11),H18,3)} -> 0.7925 | M18: Luelle | N18: B | O18: 0.7925 | Q18: Alasteir | R18: A | S18: 0.2225
H19: 9 | I19: {=INDEX(_xlfn.ANCHORARRAY($M$11),H19,1)} -> Leda | J19: {=INDEX(_xlfn.ANCHORARRAY($M$11),H19,2)} -> B | K19: {=INDEX(_xlfn.ANCHORARRAY($M$11),H19,3)} -> 0.7775 | M19: Leda | N19: B | O19: 0.7775 | Q19: Jesselyn | R19: C | S19: 0.23
H20: 10 | I20: {=INDEX(_xlfn.ANCHORARRAY($M$11),H20,1)} -> Malissa | J20: {=INDEX(_xlfn.ANCHORARRAY($M$11),H20,2)} -> C | K20: {=INDEX(_xlfn.ANCHORARRAY($M$11),H20,3)} -> 0.775 | M20: Malissa | N20: C | O20: 0.775 | Q20: Raimund | R20: C | S20: 0.25
M21: Charmine | N21: A | O21: 0.7725 | Q21: Morrie | R21: B | S21: 0.2575
H22: Rank | I22: Student name | J22: Section | K22: Percentage | M22: Valma | N22: C | O22: 0.7625 | Q22: Dory | R22: B | S22: 0.2725
H23: 1 | I23: {=INDEX(_xlfn.ANCHORARRAY($Q$11),H23,1)} -> Ginnifer | J23: {=INDEX(_xlfn.ANCHORARRAY($Q$11),H23,2)} -> C | K23: {=INDEX(_xlfn.ANCHORARRAY($Q$11),H23,3)} -> 0.1425 | M23: Davidde | N23: C | O23: 0.7625 | Q23: Willem | R23: C | S23: 0.2725
H24: 2 | I24: {=INDEX(_xlfn.ANCHORARRAY($Q$11),H24,1)} -> Ashlan | J24: {=INDEX(_xlfn.ANCHORARRAY($Q$11),H24,2)} -> B | K24: {=INDEX(_xlfn.ANCHORARRAY($Q$11),H24,3)} -> 0.1675 | M24: Inger | N24: B | O24: 0.76 | Q24: Massimiliano | R24: A | S24: 0.275
H25: 3 | I25: {=INDEX(_xlfn.ANCHORARRAY($Q$11),H25,1)} -> Blake | J25: {=INDEX(_xlfn.ANCHORARRAY($Q$11),H25,2)} -> B | K25: {=INDEX(_xlfn.ANCHORARRAY($Q$11),H25,3)} -> 0.175 | M25: Humfrid | N25: B | O25: 0.75 | Q25: Linn | R25: C | S25: 0.275
H26: 4 | I26: {=INDEX(_xlfn.ANCHORARRAY($Q$11),H26,1)} -> Jocelin | J26: {=INDEX(_xlfn.ANCHORARRAY($Q$11),H26,2)} -> A | K26: {=INDEX(_xlfn.ANCHORARRAY($Q$11),H26,3)} -> 0.1825 | M26: Zenia | N26: C | O26: 0.735 | Q26: Starlin | R26: C | S26: 0.2825
H27: 5 | I27: {=INDEX(_xlfn.ANCHORARRAY($Q$11),H27,1)} -> Berget | J27: {=INDEX(_xlfn.ANCHORARRAY($Q$11),H27,2)} -> C | K27: {=INDEX(_xlfn.ANCHORARRAY($Q$11),H27,3)} -> 0.1825 | M27: Domingo | N27: C | O27: 0.735 | Q27: Isidora | R27: C | S27: 0.3
H28: 6 | I28: {=INDEX(_xlfn.ANCHORARRAY($Q$11),H28,1)} -> Josepha | J28: {=INDEX(_xlfn.ANCHORARRAY($Q$11),H28,2)} -> C | K28: {=INDEX(_xlfn.ANCHORARRAY($Q$11),H28,3)} -> 0.1925 | M28: Jaquenette | N28: C | O28: 0.725 | Q28: Christoph | R28: C | S28: 0.3025
H29: 7 | I29: {=INDEX(_xlfn.ANCHORARRAY($Q$11),H29,1)} -> Nickie | J29: {=INDEX(_xlfn.ANCHORARRAY($Q$11),H29,2)} -> C | K29: {=INDEX(_xlfn.ANCHORARRAY($Q$11),H29,3)} -> 0.195 | M29: Rosalyn | N29: C | O29: 0.725 | Q29: Ezekiel | R29: A | S29: 0.3025
H30: 8 | I30: {=INDEX(_xlfn.ANCHORARRAY($Q$11),H30,1)} -> Alasteir | J30: {=INDEX(_xlfn.ANCHORARRAY($Q$11),H30,2)} -> A | K30: {=INDEX(_xlfn.ANCHORARRAY($Q$11),H30,3)} -> 0.2225 | M30: Patty | N30: B | O30: 0.72 | Q30: Abel | R30: A | S30: 0.3075
H31: 9 | I31: {=INDEX(_xlfn.ANCHORARRAY($Q$11),H31,1)} -> Jesselyn | J31: {=INDEX(_xlfn.ANCHORARRAY($Q$11),H31,2)} -> C | K31: {=INDEX(_xlfn.ANCHORARRAY($Q$11),H31,3)} -> 0.23 | M31: Opalina | N31: B | O31: 0.715 | Q31: Tate | R31: C | S31: 0.31
H32: 10 | I32: {=INDEX(_xlfn.ANCHORARRAY($Q$11),H32,1)} -> Raimund | J32: {=INDEX(_xlfn.ANCHORARRAY($Q$11),H32,2)} -> C | K32: {=INDEX(_xlfn.ANCHORARRAY($Q$11),H32,3)} -> 0.25 | M32: Merrick | N32: A | O32: 0.71 | Q32: Orrin | R32: C | S32: 0.31
M33: Emmanuel | N33: B | O33: 0.71 | Q33: Ekaterina | R33: B | S33: 0.3125
M34: Bethena | N34: B | O34: 0.705 | Q34: Corrine | R34: A | S34: 0.315
M35: Livia | N35: C | O35: 0.69 | Q35: Bent | R35: B | S35: 0.315
M36: Adrianne | N36: C | O36: 0.69 | Q36: Hebert | R36: A | S36: 0.315
M37: Mortimer | N37: C | O37: 0.69 | Q37: Lemmie | R37: B | S37: 0.3175
M38: Missy | N38: B | O38: 0.685 | Q38: Hector | R38: C | S38: 0.32
M39: Adah | N39: A | O39: 0.685 | Q39: Ailene | R39: C | S39: 0.3275
H40: Performance | I40: students | M40: Winslow | N40: B | O40: 0.6825 | Q40: Chris | R40: C | S40: 0.3325
H41: Excellent | I41: =COUNTIF(Student_Data!O2:O251,"Excellent") -> 4 | M41: Fran | N41: B | O41: 0.68 | Q41: Zarla | R41: B | S41: 0.3375
...

Sheet Dashboard
A1: STUDENT PERFORMANCE ANALYTICS DASHBOARD
A3: Total Students | B3: =Analysis!B2 -> 250 | C3: Average Percentage | D3: =Analysis!B3 -> 0.51177 | E3: Pass Rate | F3: =Analysis!B4 -> 0.52 | G3: Highest Percentage | H3: =Analysis!B5 -> 0.9025
A5: Lowest Percentage | B5: =Analysis!B6 -> 0.1425 | C5: Excellent Students | D5: =Analysis!B7 -> 4 | E5: At Risk Students | F5: =Analysis!B8 -> 120
